Workbook

Sheet Measure Dictionary
A1: ID | B1: Day | C1: Category | D1: Measure | E1: DAX formula | F1: Business purpose | G1: Depends on | H1: Format | I1: Expected value (Python check) | J1: Value in Power BI | K1: Matches? (formula) | L1: DAX Studio ms | M1: Tested (Y/N)
A2: D03-01 | B2: 3 | C2: Pool | D2: Total Outstanding Balance | E2: SUM ( FactLoanTape[CurrentBalance] ) | F2: Current principal outstanding on the pool. | H2: #,##0 | I2: 3.177852e+08 | K2: =IF(OR(J2="",I2=""),"",IF(ABS(J2-I2)<=MAX(0.0001,ABS(I2)*0.0001),"MATCH","CHECK"))
A3: D03-02 | B3: 3 | C3: Pool | D3: Original Balance | E3: SUM ( DimLoan[OriginalLoanAmount] ) | F3: Original principal advanced at origination. | H3: #,##0 | I3: 546073700 | K3: =IF(OR(J3="",I3=""),"",IF(ABS(J3-I3)<=MAX(0.0001,ABS(I3)*0.0001),"MATCH","CHECK"))
A4: D03-03 | B4: 3 | C4: Pool | D4: Pool Factor | E4: DIVIDE ( [Total Outstanding Balance], [Original Balance] ) | F4: Share of original balance still outstanding. | G4: Original Balance, Total Outstanding Balance | H4: 0.0% | I4: 0.581946 | K4: =IF(OR(J4="",I4=""),"",IF(ABS(J4-I4)<=MAX(0.0001,ABS(I4)*0.0001),"MATCH","CHECK"))
A5: D03-04 | B5: 3 | C5: Pool | D5: Total EAD | E5: SUM ( FactLoanTape[EAD] ) | F5: Exposure at default used for ECL. | H5: #,##0 | I5: 3.2616417e+08 | K5: =IF(OR(J5="",I5=""),"",IF(ABS(J5-I5)<=MAX(0.0001,ABS(I5)*0.0001),"MATCH","CHECK"))
A6: D03-05 | B6: 3 | C6: Counts | D6: Loan Count | E6: COUNTROWS ( FactLoanTape ) | F6: All loans on the tape. | H6: #,##0 | I6: 500 | K6: =IF(OR(J6="",I6=""),"",IF(ABS(J6-I6)<=MAX(0.0001,ABS(I6)*0.0001),"MATCH","CHECK"))
A7: D03-06 | B7: 3 | C7: Counts | D7: Active Loans | E7: CALCULATE ( COUNTROWS ( FactLoanTape ), FactLoanTape[CurrentBalance] > 0 ) | F7: Loans with a positive balance (24 loans carry zero balance). | H7: #,##0 | I7: 476 | K7: =IF(OR(J7="",I7=""),"",IF(ABS(J7-I7)<=MAX(0.0001,ABS(I7)*0.0001),"MATCH","CHECK"))
A8: D03-07 | B8: 3 | C8: Counts | D8: Defaulted Loans | E8: CALCULATE ( COUNTROWS ( FactLoanTape ), FactLoanTape[IsDefaulted] = 1 ) | F8: Loans flagged Default or Repossessed. | H8: #,##0 | I8: 9 | K8: =IF(OR(J8="",I8=""),"",IF(ABS(J8-I8)<=MAX(0.0001,ABS(I8)*0.0001),"MATCH","CHECK"))
A9: D03-08 | B9: 3 | C9: Counts | D9: Prepaid Loans | E9: CALCULATE ( COUNTROWS ( FactLoanTape ), FactLoanTape[PrepaymentAmount] > 0 ) | F9: Loans with a voluntary prepayment. | H9: #,##0
A10: D03-09 | B10: 3 | C10: Balances | D10: Defaulted Balance | E10: CALCULATE ( [Total Outstanding Balance], FactLoanTape[IsDefaulted] = 1 ) | F10: Outstanding balance of defaulted loans. | G10: Total Outstanding Balance | H10: #,##0
A11: D03-10 | B11: 3 | C11: Delinquency | D11: Balance Current | E11: CALCULATE ( [Total Outstanding Balance], FactLoanTape[DelinquencyStatus] = "Current" ) | F11: Balance with no arrears. | G11: Total Outstanding Balance | H11: #,##0
A12: D03-11 | B12: 3 | C12: Delinquency | D12: Balance 1-29 DPD | E12: CALCULATE ( [Total Outstanding Balance], FactLoanTape[DelinquencyStatus] = "1-29 DPD" ) | F12: Balance 1-29 days past due. | G12: Total Outstanding Balance | H12: #,##0
A13: D03-12 | B13: 3 | C13: Delinquency | D13: Balance 30 DPD | E13: CALCULATE ( [Total Outstanding Balance], FactLoanTape[DelinquencyStatus] = "30-59 DPD" ) | F13: Balance 30-59 days past due. | G13: Total Outstanding Balance | H13: #,##0
A14: D03-13 | B14: 3 | C14: Delinquency | D14: Balance 60 DPD | E14: CALCULATE ( [Total Outstanding Balance], FactLoanTape[DelinquencyStatus] = "60-89 DPD" ) | F14: Balance 60-89 days past due. | G14: Total Outstanding Balance | H14: #,##0
A15: D03-14 | B15: 3 | C15: Delinquency | D15: Balance 90 DPD | E15: CALCULATE ( [Total Outstanding Balance], FactLoanTape[DelinquencyStatus] = "90-119 DPD" ) | F15: Balance 90-119 days past due. | G15: Total Outstanding Balance | H15: #,##0
A16: D03-15 | B16: 3 | C16: Delinquency | D16: Balance 120+ DPD | E16: CALCULATE ( [Total Outstanding Balance], FactLoanTape[DelinquencyStatus] IN { "120+ DPD", "Default", "Repossessed" } ) | F16: Balance 120+ DPD plus Default/Repossessed. | G16: Total Outstanding Balance | H16: #,##0
A17: D03-16 | B17: 3 | C17: Delinquency | D17: Delinquent 30+ Balance | E17: CALCULATE ( [Total Outstanding Balance], FactLoanTape[DelinquencyDays] >= 30 ) | F17: Balance 30 or more days past due. | G17: Total Outstanding Balance | H17: #,##0
A18: D03-17 | B18: 3 | C18: Delinquency | D18: Delinquent 30+ % | E18: DIVIDE ( [Delinquent 30+ Balance], [Total Outstanding Balance] ) | F18: 30+ DPD as % of pool balance (SMA-1 and worse). | G18: Delinquent 30+ Balance, Total Outstanding Balance | H18: 0.0% | I18: 0.141141 | K18: =IF(OR(J18="",I18=""),"",IF(ABS(J18-I18)<=MAX(0.0001,ABS(I18)*0.0001),"MATCH","CHECK"))
A19: D03-18 | B19: 3 | C19: Delinquency | D19: Delinquent 60+ Balance | E19: CALCULATE ( [Total Outstanding Balance], FactLoanTape[DelinquencyDays] >= 60 ) | F19: Balance 60 or more days past due. | G19: Total Outstanding Balance | H19: #,##0
A20: D03-19 | B20: 3 | C20: Delinquency | D20: Delinquent 60+ % | E20: DIVIDE ( [Delinquent 60+ Balance], [Total Outstanding Balance] ) | F20: 60+ DPD as % of pool; drives the delinquency trigger. | G20: Delinquent 60+ Balance, Total Outstanding Balance | H20: 0.0% | I20: 0.105873 | K20: =IF(OR(J20="",I20=""),"",IF(ABS(J20-I20)<=MAX(0.0001,ABS(I20)*0.0001),"MATCH","CHECK"))
A21: D03-20 | B21: 3 | C21: Delinquency | D21: Delinquent 90+ Balance | E21: CALCULATE ( [Total Outstanding Balance], FactLoanTape[DelinquencyDays] >= 90 ) | F21: Balance 90 or more days past due (NPA). | G21: Total Outstanding Balance | H21: #,##0
A22: D03-21 | B22: 3 | C22: Delinquency | D22: Delinquent 90+ % | E22: DIVIDE ( [Delinquent 90+ Balance], [Total Outstanding Balance] ) | F22: NPA ratio. | G22: Delinquent 90+ Balance, Total Outstanding Balance | H22: 0.0% | I22: 0.055695 | K22: =IF(OR(J22="",I22=""),"",IF(ABS(J22-I22)<=MAX(0.0001,ABS(I22)*0.0001),"MATCH","CHECK"))
A23: D03-22 | B23: 3 | C23: Weighted avg | D23: WAC | E23: DIVIDE ( SUMX ( FactLoanTape, RELATED ( DimLoan[InterestRate] ) * FactLoanTape[CurrentBalance] ), [Total Outstanding Balance] ) / 100 | F23: Weighted-average coupon (rate in tape is in % points). | G23: Total Outstanding Balance | H23: 0.00% | I23: 0.109455 | K23: =IF(OR(J23="",I23=""),"",IF(ABS(J23-I23)<=MAX(0.0001,ABS(I23)*0.0001),"MATCH","CHECK"))
A24: D03-23 | B24: 3 | C24: Weighted avg | D24: WAM | E24: DIVIDE ( SUMX ( FactLoanTape, FactLoanTape[RemainingTerm] * FactLoanTape[CurrentBalance] ), [Total Outstanding Balance] ) | F24: Weighted-average remaining maturity (months). | G24: Total Outstanding Balance | H24: 0.0 | I24: 45.142781 | K24: =IF(OR(J24="",I24=""),"",IF(ABS(J24-I24)<=MAX(0.0001,ABS(I24)*0.0001),"MATCH","CHECK"))
A25: D03-24 | B25: 3 | C25: Weighted avg | D25: WALA | E25: DIVIDE ( SUMX ( FactLoanTape, FactLoanTape[MonthsOnBook] * FactLoanTape[CurrentBalance] ), [Total Outstanding Balance] ) | F25: Weighted-average loan age (months on book). | G25: Total Outstanding Balance | H25: 0.0 | I25: 16.755706 | K25: =IF(OR(J25="",I25=""),"",IF(ABS(J25-I25)<=MAX(0.0001,ABS(I25)*0.0001),"MATCH","CHECK"))
A26: D03-25 | B26: 3 | C26: Weighted avg | D26: WALT | E26: DIVIDE ( SUMX ( FactLoanTape, RELATED ( DimLoan[OriginalTerm] ) * FactLoanTape[CurrentBalance] ), [Total Outstanding Balance] ) | F26: Weighted-average original loan term (months). | G26: Total Outstanding Balance | H26: 0.0 | I26: 61.898488 | K26: =IF(OR(J26="",I26=""),"",IF(ABS(J26-I26)<=MAX(0.0001,ABS(I26)*0.0001),"MATCH","CHECK"))
A27: D03-26 | B27: 3 | C27: Weighted avg | D27: WA LTV Origination | E27: DIVIDE ( SUMX ( FactLoanTape, FactLoanTape[LTV_AtOrigination] * FactLoanTape[CurrentBalance] ), [Total Outstanding Balance] ) | F27: Balance-weighted LTV at origination. | G27: Total Outstanding Balance | H27: 0.0%
A28: D03-27 | B28: 3 | C28: Weighted avg | D28: WA LTV Current | E28: DIVIDE ( SUMX ( FactLoanTape, FactLoanTape[LTV_Current] * FactLoanTape[CurrentBalance] ), [Total Outstanding Balance] ) | F28: Balance-weighted current LTV. | G28: Total Outstanding Balance | H28: 0.0% | I28: 0.675413 | K28: =IF(OR(J28="",I28=""),"",IF(ABS(J28-I28)<=MAX(0.0001,ABS(I28)*0.0001),"MATCH","CHECK"))
A29: D03-28 | B29: 3 | C29: Weighted avg | D29: WA CIBIL | E29: DIVIDE ( SUMX ( FactLoanTape, FactLoanTape[CIBIL_Score_Current] * FactLoanTape[CurrentBalance] ), [Total Outstanding Balance] ) | F29: Balance-weighted current CIBIL score. | G29: Total Outstanding Balance | H29: 0 | I29: 742.43926 | K29: =IF(OR(J29="",I29=""),"",IF(ABS(J29-I29)<=MAX(0.0001,ABS(I29)*0.0001),"MATCH","CHECK"))
A30: D03-29 | B30: 3 | C30: Weighted avg | D30: WA CIBIL Origination | E30: DIVIDE ( SUMX ( FactLoanTape, FactLoanTape[CIBIL_Score_Origination] * FactLoanTape[CurrentBalance] ), [Total Outstanding Balance] ) | F30: Balance-weighted CIBIL at origination. | G30: Total Outstanding Balance | H30: 0
A31: D03-30 | B31: 3 | C31: Weighted avg | D31: WA DTI | E31: DIVIDE ( SUMX ( FactLoanTape, FactLoanTape[DTI_Ratio] * FactLoanTape[CurrentBalance] ), [Total Outstanding Balance] ) | F31: Balance-weighted debt-to-income. | G31: Total Outstanding Balance | H31: 0.0% | I31: 0.239732 | K31: =IF(OR(J31="",I31=""),"",IF(ABS(J31-I31)<=MAX(0.0001,ABS(I31)*0.0001),"MATCH","CHECK"))
A32: D03-31 | B32: 3 | C32: Pool | D32: Average Loan Balance | E32: DIVIDE ( [Total Outstanding Balance], [Active Loans] ) | F32: Mean balance of active loans. | G32: Active Loans, Total Outstanding Balance | H32: #,##0
A33: D03-32 | B33: 3 | C33: Pool | D33: Largest Loan Balance | E33: MAX ( FactLoanTape[CurrentBalance] ) | F33: Single largest exposure. | H33: #,##0
A34: D03-33 | B34: 3 | C34: Pool | D34: Insured Loan % | E34: DIVIDE ( CALCULATE ( [Total Outstanding Balance], DimLoan[HasInsurance] = 1 ), [Total Outstanding Balance] ) | F34: Balance share with any vehicle insurance. | G34: Total Outstanding Balance | H34: 0.0%
A35: D03-34 | B35: 3 | C35: Pool | D35: New Vehicle % | E35: DIVIDE ( CALCULATE ( [Total Outstanding Balance], DimVehicle[IsNewVehicle] = 1 ), [Total Outstanding Balance] ) | F35: Balance share financing new vehicles. | G35: Total Outstanding Balance | H35: 0.0%
A36: D03-35 | B36: 3 | C36: Pool | D36: Modified Loan % | E36: DIVIDE ( CALCULATE ( COUNTROWS ( FactLoanTape ), DimLoan[IsModified] = 1 ), [Loan Count] ) | F36: Share of loans restructured (deferral, extension, rate cut). | G36: Loan Count | H36: 0.0%
A37: D03-36 | B37: 3 | C37: Loss | D37: Total Prepayments | E37: SUM ( FactLoanTape[PrepaymentAmount] ) | F37: Voluntary prepayments recorded on the tape. | H37: #,##0
A38: D03-37 | B38: 3 | C38: Loss | D38: Total Loss Amount | E38: SUM ( FactLoanTape[LossAmount] ) | F38: Gross realised loss on the tape. | H38: #,##0
A39: D03-38 | B39: 3 | C39: Loss | D39: Total Recoveries | E39: SUM ( FactLoanTape[RecoveryAmount] ) | F39: Recoveries on the tape. | H39: #,##0
A40: D03-39 | B40: 3 | C40: Loss | D40: Total Net Loss (Tape) | E40: SUM ( FactLoanTape[NetLoss] ) | F40: Net realised loss on the tape. | H40: #,##0
...

Sheet Summary
A1: Day | B1: Focus | C1: Measures
A2: 3 | B2: Core pool, delinquency and weighted-average measures | C2: =COUNTIF('Measure Dictionary'!B:B,3) -> 40
A3: 4 | B3: Time intelligence and trend alerts | C3: =COUNTIF('Measure Dictionary'!B:B,4) -> 24
A4: 5 | B4: Advanced DAX, virtual tables, concentration | C4: =COUNTIF('Measure Dictionary'!B:B,5) -> 14
A5: 6 | B5: Waterfall, tranche allocation and trigger testing | C5: =COUNTIF('Measure Dictionary'!B:B,6) -> 31
A6: 7 | B6: DPD distribution, roll rates and ageing | C6: =COUNTIF('Measure Dictionary'!B:B,7) -> 24
A7: 8 | B7: Vintage / static pool analysis | C7: =COUNTIF('Measure Dictionary'!B:B,8) -> 14
A8: 9 | B8: IFRS 9 ECL framework | C8: =COUNTIF('Measure Dictionary'!B:B,9) -> 26
A9: 10 | B9: Stress testing and what-if | C9: =COUNTIF('Measure Dictionary'!B:B,10) -> 33
A10: 11 | B10: Investor reporting and data tape | C10: =COUNTIF('Measure Dictionary'!B:B,11) -> 10
A11: 12 | B11: Security, governance and validation | C11: =COUNTIF('Measure Dictionary'!B:B,12) -> 6
B12: Total | C12: =SUM(C2:C11) -> 222
B13: Brief requirement | C13: 80
B14: Meets 80+ requirement? | C14: =IF(C12>=C13,"YES","NO") -> YES

Sheet Parameters
A1: Parameter table | B1: DAX | C1: Purpose
A2: ParamDefaultMult | B2: GENERATESERIES ( 0.5, 5, 0.1 ) | C2: Default-rate multiplier (x)
A3: ParamRecoveryHaircut | B3: GENERATESERIES ( 0, 0.5, 0.05 ) | C3: Recovery haircut = additive LGD (pts)
A4: ParamCPRChange | B4: GENERATESERIES ( -0.1, 0.1, 0.01 ) | C4: Change in annual CPR (pts)
A5: ParamRateShock | B5: GENERATESERIES ( 0, 500, 25 ) | C5: Interest-rate shock (bps)
A6: ParamStage2DPD | B6: GENERATESERIES ( 0, 120, 5 ) | C6: Stage 2 DPD threshold (tape = 30, brief = 60)
A7: ParamStage3DPD | B7: GENERATESERIES ( 60, 180, 5 ) | C7: Stage 3 DPD threshold (tape = 90, brief = 120)
A8: ParamDelinqTrigger | B8: GENERATESERIES ( 0.05, 0.25, 0.005 ) | C8: Delinquency trigger level
A9: ParamCNLTrigger | B9: GENERATESERIES ( 0.005, 0.1, 0.0025 ) | C9: Cumulative net loss trigger level
A10: ParamOCTrigger | B10: GENERATESERIES ( 1, 1.3, 0.01 ) | C10: OC ratio trigger (minimum)
